Workbook

Sheet Summary
A1: FreedomBot v1 UI test run — 2026-09-30
A2: Environment: local QA copy (API :8011, UI :3011), fresh databases bizos_qa_*, clients Acme (all domains), Globex (base package), Initrode (new from template). Fake data only. Model: openai gpt-4.1-mini.
A4: Module | B4: Name | C4: Pass | D4: Fail | E4: Partial | F4: Total | G4: Pass rate
A5: M01 | B5: Isolated FreedomBot v1 per client | C5: =COUNTIFS(Results!$A$2:$A$381,"M01-*",Results!$B$2:$B$381,"Pass") | D5: =COUNTIFS(Results!$A$2:$A$381,"M01-*",Results!$B$2:$B$381,"Fail") | E5: =COUNTIFS(Results!$A$2:$A$381,"M01-*",Results!$B$2:$B$381,"Partial") | F5: =SUM(C5:E5) | G5: =IF(F5=0,0,C5/F5)
A6: M02 | B6: One company chat | C6: =COUNTIFS(Results!$A$2:$A$381,"M02-*",Results!$B$2:$B$381,"Pass") | D6: =COUNTIFS(Results!$A$2:$A$381,"M02-*",Results!$B$2:$B$381,"Fail") | E6: =COUNTIFS(Results!$A$2:$A$381,"M02-*",Results!$B$2:$B$381,"Partial") | F6: =SUM(C6:E6) | G6: =IF(F6=0,0,C6/F6)
A7: M03 | B7: Phase 1 domains | C7: =COUNTIFS(Results!$A$2:$A$381,"M03-*",Results!$B$2:$B$381,"Pass") | D7: =COUNTIFS(Results!$A$2:$A$381,"M03-*",Results!$B$2:$B$381,"Fail") | E7: =COUNTIFS(Results!$A$2:$A$381,"M03-*",Results!$B$2:$B$381,"Partial") | F7: =SUM(C7:E7) | G7: =IF(F7=0,0,C7/F7)
A8: M04 | B8: Approved memory + conflicts | C8: =COUNTIFS(Results!$A$2:$A$381,"M04-*",Results!$B$2:$B$381,"Pass") | D8: =COUNTIFS(Results!$A$2:$A$381,"M04-*",Results!$B$2:$B$381,"Fail") | E8: =COUNTIFS(Results!$A$2:$A$381,"M04-*",Results!$B$2:$B$381,"Partial") | F8: =SUM(C8:E8) | G8: =IF(F8=0,0,C8/F8)
A9: M05 | B9: Role-aware access | C9: =COUNTIFS(Results!$A$2:$A$381,"M05-*",Results!$B$2:$B$381,"Pass") | D9: =COUNTIFS(Results!$A$2:$A$381,"M05-*",Results!$B$2:$B$381,"Fail") | E9: =COUNTIFS(Results!$A$2:$A$381,"M05-*",Results!$B$2:$B$381,"Partial") | F9: =SUM(C9:E9) | G9: =IF(F9=0,0,C9/F9)
A10: M06 | B10: Advise/Draft/Approve/Auto + audit | C10: =COUNTIFS(Results!$A$2:$A$381,"M06-*",Results!$B$2:$B$381,"Pass") | D10: =COUNTIFS(Results!$A$2:$A$381,"M06-*",Results!$B$2:$B$381,"Fail") | E10: =COUNTIFS(Results!$A$2:$A$381,"M06-*",Results!$B$2:$B$381,"Partial") | F10: =SUM(C10:E10) | G10: =IF(F10=0,0,C10/F10)
A11: M07 | B11: Licensed judgment + regulated data | C11: =COUNTIFS(Results!$A$2:$A$381,"M07-*",Results!$B$2:$B$381,"Pass") | D11: =COUNTIFS(Results!$A$2:$A$381,"M07-*",Results!$B$2:$B$381,"Fail") | E11: =COUNTIFS(Results!$A$2:$A$381,"M07-*",Results!$B$2:$B$381,"Partial") | F11: =SUM(C11:E11) | G11: =IF(F11=0,0,C11/F11)
A12: M08 | B12: n8n integrations | C12: =COUNTIFS(Results!$A$2:$A$381,"M08-*",Results!$B$2:$B$381,"Pass") | D12: =COUNTIFS(Results!$A$2:$A$381,"M08-*",Results!$B$2:$B$381,"Fail") | E12: =COUNTIFS(Results!$A$2:$A$381,"M08-*",Results!$B$2:$B$381,"Partial") | F12: =SUM(C12:E12) | G12: =IF(F12=0,0,C12/F12)
A13: M09 | B13: Inefficiency alerts v1 | C13: =COUNTIFS(Results!$A$2:$A$381,"M09-*",Results!$B$2:$B$381,"Pass") | D13: =COUNTIFS(Results!$A$2:$A$381,"M09-*",Results!$B$2:$B$381,"Fail") | E13: =COUNTIFS(Results!$A$2:$A$381,"M09-*",Results!$B$2:$B$381,"Partial") | F13: =SUM(C13:E13) | G13: =IF(F13=0,0,C13/F13)
A14: M10 | B14: Default chat interface | C14: =COUNTIFS(Results!$A$2:$A$381,"M10-*",Results!$B$2:$B$381,"Pass") | D14: =COUNTIFS(Results!$A$2:$A$381,"M10-*",Results!$B$2:$B$381,"Fail") | E14: =COUNTIFS(Results!$A$2:$A$381,"M10-*",Results!$B$2:$B$381,"Partial") | F14: =SUM(C14:E14) | G14: =IF(F14=0,0,C14/F14)
A15: M11 | B15: Paid client handoff | C15: =COUNTIFS(Results!$A$2:$A$381,"M11-*",Results!$B$2:$B$381,"Pass") | D15: =COUNTIFS(Results!$A$2:$A$381,"M11-*",Results!$B$2:$B$381,"Fail") | E15: =COUNTIFS(Results!$A$2:$A$381,"M11-*",Results!$B$2:$B$381,"Partial") | F15: =SUM(C15:E15) | G15: =IF(F15=0,0,C15/F15)
A16: M12 | B16: Configure first client | C16: =COUNTIFS(Results!$A$2:$A$381,"M12-*",Results!$B$2:$B$381,"Pass") | D16: =COUNTIFS(Results!$A$2:$A$381,"M12-*",Results!$B$2:$B$381,"Fail") | E16: =COUNTIFS(Results!$A$2:$A$381,"M12-*",Results!$B$2:$B$381,"Partial") | F16: =SUM(C16:E16) | G16: =IF(F16=0,0,C16/F16)
A17: M13 | B17: Isolation & launch acceptance | C17: =COUNTIFS(Results!$A$2:$A$381,"M13-*",Results!$B$2:$B$381,"Pass") | D17: =COUNTIFS(Results!$A$2:$A$381,"M13-*",Results!$B$2:$B$381,"Fail") | E17: =COUNTIFS(Results!$A$2:$A$381,"M13-*",Results!$B$2:$B$381,"Partial") | F17: =SUM(C17:E17) | G17: =IF(F17=0,0,C17/F17)
A18: M14 | B18: Routine support to Cepoch | C18: =COUNTIFS(Results!$A$2:$A$381,"M14-*",Results!$B$2:$B$381,"Pass") | D18: =COUNTIFS(Results!$A$2:$A$381,"M14-*",Results!$B$2:$B$381,"Fail") | E18: =COUNTIFS(Results!$A$2:$A$381,"M14-*",Results!$B$2:$B$381,"Partial") | F18: =SUM(C18:E18) | G18: =IF(F18=0,0,C18/F18)
A19: M15 | B19: Owner view | C19: =COUNTIFS(Results!$A$2:$A$381,"M15-*",Results!$B$2:$B$381,"Pass") | D19: =COUNTIFS(Results!$A$2:$A$381,"M15-*",Results!$B$2:$B$381,"Fail") | E19: =COUNTIFS(Results!$A$2:$A$381,"M15-*",Results!$B$2:$B$381,"Partial") | F19: =SUM(C19:E19) | G19: =IF(F19=0,0,C19/F19)
A20: M16 | B20: Resale price rules | C20: =COUNTIFS(Results!$A$2:$A$381,"M16-*",Results!$B$2:$B$381,"Pass") | D20: =COUNTIFS(Results!$A$2:$A$381,"M16-*",Results!$B$2:$B$381,"Fail") | E20: =COUNTIFS(Results!$A$2:$A$381,"M16-*",Results!$B$2:$B$381,"Partial") | F20: =SUM(C20:E20) | G20: =IF(F20=0,0,C20/F20)
A21: M17 | B21: Consult pricing math | C21: =COUNTIFS(Results!$A$2:$A$381,"M17-*",Results!$B$2:$B$381,"Pass") | D21: =COUNTIFS(Results!$A$2:$A$381,"M17-*",Results!$B$2:$B$381,"Fail") | E21: =COUNTIFS(Results!$A$2:$A$381,"M17-*",Results!$B$2:$B$381,"Partial") | F21: =SUM(C21:E21) | G21: =IF(F21=0,0,C21/F21)
A22: M18 | B22: Baseline vs after | C22: =COUNTIFS(Results!$A$2:$A$381,"M18-*",Results!$B$2:$B$381,"Pass") | D22: =COUNTIFS(Results!$A$2:$A$381,"M18-*",Results!$B$2:$B$381,"Fail") | E22: =COUNTIFS(Results!$A$2:$A$381,"M18-*",Results!$B$2:$B$381,"Partial") | F22: =SUM(C22:E22) | G22: =IF(F22=0,0,C22/F22)
A23: M19 | B23: No Founder Mode | C23: =COUNTIFS(Results!$A$2:$A$381,"M19-*",Results!$B$2:$B$381,"Pass") | D23: =COUNTIFS(Results!$A$2:$A$381,"M19-*",Results!$B$2:$B$381,"Fail") | E23: =COUNTIFS(Results!$A$2:$A$381,"M19-*",Results!$B$2:$B$381,"Partial") | F23: =SUM(C23:E23) | G23: =IF(F23=0,0,C23/F23)
A24: Total | C24: =SUM(C5:C23) | D24: =SUM(D5:D23) | E24: =SUM(E5:E23) | F24: =SUM(F5:F23) | G24: =IF(F24=0,0,C24/F24)
A26: Open bugs by severity (fixed ones excluded)
A27: Critical | B27: =COUNTIFS(Bugs!$B$2:$B$31,"Critical",Bugs!$F$2:$F$31,"Open")
A28: High | B28: =COUNTIFS(Bugs!$B$2:$B$31,"High",Bugs!$F$2:$F$31,"Open")
A29: Medium | B29: =COUNTIFS(Bugs!$B$2:$B$31,"Medium",Bugs!$F$2:$F$31,"Open")
A30: Low | B30: =COUNTIFS(Bugs!$B$2:$B$31,"Low",Bugs!$F$2:$F$31,"Open")
A32: Legend: Pass = UI behaviour, permissions, stored data and audit all matched. Partial = core control held but a secondary expectation failed. Fail = expected result not met or feature missing.

Sheet Results
A1: Test ID | B1: Pass/Fail | C1: Actual Result | D1: Screenshot | E1: Bug ID | F1: Notes | G1: Module
A2: M01-01 | B2: Pass | C2: Fact "BLUEFALCON-7" saved in Acme; Globex chat and memory search found nothing. | G2: M01 Isolated FreedomBot v1 per client
A3: M01-02 | B3: Pass | C3: Fact "REDOTTER-3" saved in Globex; Acme chat and search found nothing. | G3: M01 Isolated FreedomBot v1 per client
A4: M01-03 | B4: Pass | C4: Approved "Parking policy" created in Acme; after logout, Globex memory list and chat had no trace. | G4: M01 Isolated FreedomBot v1 per client
A5: M01-04 | B5: Pass | C5: Same email exists in Acme and Globex as two separate user IDs; an Acme-only note was not searchable from Globex. | E5: BUG-26 | F5: Login without workspace slug returns "Invalid credentials" instead of asking which company. | G5: M01 Isolated FreedomBot v1 per client
A6: M01-05 | B6: Pass | C6: Signed out of Acme and into Globex in the same browser; header shows GLOBEX LTD and chat is empty. | D6: screenshots/memory_globex.png | G6: M01 Isolated FreedomBot v1 per client
A7: M01-06 | B7: Pass | C7: Retest after fix: tab 1 switched to GLOBEX LTD with a notice; API refuses a stale tab with 409. | D7: screenshots/retest_M01-06_tab1_after_switch.png | E7: BUG-02 | F7: Originally failed: Tab 1 still shows ACME CORP after tab 2 signed into Globex, but tab 1's chat answered "You are working for Globex Ltd ... discount 5%". | G7: M01 Isolated FreedomBot v1 per client
A8: M01-07 | B8: Pass | C8: Forklift SOP added to Acme; Globex chat said no such SOP exists. | G8: M01 Isolated FreedomBot v1 per client
A9: M01-08 | B9: Pass | C9: Changed Acme max emails per run to 2; Globex stayed at 5. | G9: M01 Isolated FreedomBot v1 per client
A10: M01-09 | B10: Pass | C10: Set an Acme per-tool mode (crm_create_note ADVISE); Globex unchanged. | G10: M01 Isolated FreedomBot v1 per client
A11: M01-10 | B11: Pass | C11: Finance granted to the shared user in Acme only; Globex scopes empty. Acme admin patching a Globex user ID got 404. | G11: M01 Isolated FreedomBot v1 per client
A12: M01-11 | B12: Pass | C12: Retest after fix: Conversations list shows the user's own threads; reopening restores them; Globex user sees none. | D12: screenshots/retest_M01-11_conversation_list.png | E12: BUG-11 | F12: Originally failed: No chat-history view exists in the UI. Sessions are stored per workspace database, but users cannot open past threads. | G12: M01 Isolated FreedomBot v1 per client
A13: M01-12 | B13: Pass | C13: Retest after fix: Acme admin removed 'Parking policy'; it left the list and answers, audit logged MEMORY_ARCHIVED; Globex memory unchanged. | D13: screenshots/retest_M01-12_after_remove.png | E13: BUG-14 | F13: Originally failed: No delete or deactivate function for memory in the API or UI. | G13: M01 Isolated FreedomBot v1 per client
A14: M01-13 | B14: Pass | C14: Same question gave 15% in Acme and 5% in Globex. | G14: M01 Isolated FreedomBot v1 per client
A15: M01-14 | B15: Pass | C15: Corrected Acme discount to 18%; Acme answers 18%, Globex still 5%. | G15: M01 Isolated FreedomBot v1 per client
A16: M01-15 | B16: Pass | C16: Header shows the correct company name (ACME CORP / GLOBEX LTD). | D16: screenshots/chat_empty_acme.png | G16: M01 Isolated FreedomBot v1 per client
A17: M01-16 | B17: Pass | C17: Acme search returned "Pricing discount" only; Globex returned "Standard discount" only. | G17: M01 Isolated FreedomBot v1 per client
A18: M01-17 | B18: Pass | C18: Acme audit had 60 rows, all with Acme's client ID and zero Globex user IDs. | G18: M01 Isolated FreedomBot v1 per client
A19: M01-18 | B19: Pass | C19: After logout from Acme and login to Globex, no Acme chat turns or Acme-only memory items were shown. | D19: screenshots/memory_globex.png | G19: M01 Isolated FreedomBot v1 per client
A20: M01-19 | B20: Pass | C20: Requesting a Globex memory ID from Acme returned 404 echoing only the requested ID. Cross-client ticket returned 404. | F20: Note: invalid execution_mode is silently ignored rather than rejected. | G20: M01 Isolated FreedomBot v1 per client
A21: M01-20 | B21: Pass | C21: Retest after fix: new client shows no alerts, no baseline and no price; quoting asks for rules first. | D21: screenshots/retest_M01-20_pricing.png | E21: BUG-08 | F21: Originally failed: New client "Initrode" had clean memory, but showed Acme's payroll inefficiency alerts, Acme's payroll baseline and the $12,000 placeholder price. | G21: M01 Isolated FreedomBot v1 per client
A22: M02-01 | B22: Pass | C22: Login lands on /chat; chat is the main screen. | D22: screenshots/chat_empty_acme.png | G22: M02 One company chat
A23: M02-02 | B23: Pass | C23: "I am FreedomBot, an AI assistant for Acme Corp." | G23: M02 One company chat
A24: M02-03 | B24: Pass | C24: Nav shows Ask FreedomBot, Memory, Approvals, Support, Audit; no persona or bot selector. | G24: M02 One company chat
A25: M02-04 | B25: Pass | C25: No Bronze/Silver/Gold anywhere in UI text or source. | G25: M02 One company chat
A26: M02-05 | B26: Pass | C26: Strategy then operations questions answered in one session. | D26: screenshots/chat_multi_domain.png | G26: M02 One company chat
A27: M02-06 | B27: Pass | C27: Exec user moved ops to finance in one session; payment terms and refund period answered. | E27: BUG-20 | F27: Operator with finance scope got a false "restricted to Finance" reply in the UI run. | G27: M02 One company chat
A28: M02-07 | B28: Pass | C28: Back to strategy in the same session; bot linked discount policy to the pipeline goal from earlier. | G28: M02 One company chat
A29: M02-08 | B29: Pass | C29: "What about that process — the payroll one" resolved to the payroll SOP. | G29: M02 One company chat
A30: M02-09 | B30: Pass | C30: Headcount and sites given once were reused in ops and finance turns without re-asking. | F30: Bot assumed the warehouses are rented without labelling it as an inference. | G30: M02 One company chat
A31: M02-10 | B31: Pass | C31: One message answered both strategy goal and operating hours. | G31: M02 One company chat
A32: M02-11 | B32: Partial | C32: Discount policy answered, but CRM part wrongly said there are no Contoso contacts (two exist). | E32: BUG-07 | G32: M02 One company chat
A33: M02-12 | B33: Pass | C33: Employee in a strategy thread asked for invoice amount; answer said Finance area is restricted. | G33: M02 One company chat
A34: M02-13 | B34: Pass | C34: Nickname given in one chat was not known in a new chat; same chat still recalled it. | G34: M02 One company chat
A35: M02-14 | B35: Pass | C35: Retest after fix: earlier thread reopened from the Conversations list. | D35: screenshots/retest_M01-11_reopened.png | E35: BUG-11 | F35: Originally failed: Existing thread is lost on refresh or navigation; there is no way to return to a previous chat. | G35: M02 One company chat
A36: M02-15 | B36: Pass | C36: "Summarize it in two bullets" correctly referred to the payroll approval step. | G36: M02 One company chat
A37: M02-16 | B37: Pass | C37: Six rapid domain switches; each answered, no switching UI. | G37: M02 One company chat
A38: M02-17 | B38: Pass | C38: Did not invent a finance bot; said it can help with finance directly. | G38: M02 One company chat
A39: M02-18 | B39: Pass | C39: "I am not Jeanne or any person." | G39: M02 One company chat
A40: M02-19 | B40: Pass | C40: Retest after fix: 4 answers before and after refresh. | E40: BUG-11 | F40: Originally failed: Refresh during a multi-domain conversation cleared all turns (1 turn before, 0 after). | G40: M02 One company chat
...

Sheet Bugs
A1: Bug ID | B1: Severity | C1: Title | D1: Description | E1: Where | F1: Status | G1: Tests affected (count)
A2: BUG-01 | B2: Critical | C2: Owner portfolio is readable and writable across clients | D2: Any client's ADMIN can GET /api/owner/portfolio (all clients' tickets, revenue, risk) and PUT another client's portfolio. Globex admin overwrote Acme's status. | E2: app/api/owner.py | F2: Fixed 2026-09-30 | G2: =COUNTIF(Results!$E$2:$E$381,A2)
A3: BUG-02 | B3: High | C3: Two tabs in one browser mix clients | D3: Session cookie is shared per browser. After tab 2 signs into Globex, tab 1 still shows ACME CORP but answers with Globex data. | E3: ui/src/components/SessionProvider.tsx | F3: Fixed 2026-09-30 | G3: =COUNTIF(Results!$E$2:$E$381,A3)
A4: BUG-03 | B4: High | C4: Chat claims actions it never took | D4: Bot says "submitted for approval" or "Decision recorded" with no tool call. Email sends are routed to the general domain, where email_send_message is not exposed. | E4: bizos/agents/persona.py (routing), bizos/domains/packs.py | F4: Partly fixed 2026-09-30 (email routing + false-claim check) | G4: =COUNTIF(Results!$E$2:$E$381,A4)
A5: BUG-04 | B5: High | C5: Approvals queue ignores data areas | D5: Viewer and Employee without finance access see finance adjustment amounts and customers on the Approvals page and API. | E5: app/api/approvals.py | F5: Fixed 2026-09-30 | G5: =COUNTIF(Results!$E$2:$E$381,A5)
A6: BUG-05 | B6: High | C6: Raw sensitive values in audit | D6: MEMORY_READ audit rows store the full user query, including fake SSN and MRN. | E6: bizos/memory/store.py (_audit on search) | F6: Fixed 2026-09-30 | G6: =COUNTIF(Results!$E$2:$E$381,A6)
A7: BUG-06 | B7: High | C7: Approved CRM tag wipes lifecycle | D7: crm_tag_lead payload carried lifecycle "", which blanked Tom Reyes's lifecycle when executed. | E7: bizos/tools/crm.py / connectors/mock_crm.py | F7: Open | G7: =COUNTIF(Results!$E$2:$E$381,A7)
A8: BUG-07 | B8: Medium | C8: CRM contact search fails on full names | D8: Search matches one column at a time, so "Tom Reyes" returns zero and the bot says the contact doesn't exist. | E8: bizos/connectors/mock_crm.py:50 | F8: Open | G8: =COUNTIF(Results!$E$2:$E$381,A8)
A9: BUG-08 | B9: High | C9: New clients inherit Acme demo defaults | D9: Clients without stored values get Acme's payroll alerts, payroll baseline and the $12,000 price/revenue placeholder. | E9: bizos/insights.py, bizos/pricing.py | F9: Fixed 2026-09-30 | G9: =COUNTIF(Results!$E$2:$E$381,A9)
A10: BUG-09 | B10: Medium | C10: Partial pricing save resets price | D10: PUT resale-rules with only notes resets price and cost to $12,000/$7,200 via request-model defaults. | E10: app/api/admin.py ResaleRulesBody | F10: Fixed 2026-09-30 | G10: =COUNTIF(Results!$E$2:$E$381,A10)
A11: BUG-10 | B11: Medium | C11: Pricing validation gaps | D11: $0 price accepted, cost above price accepted (-400% margin), blank autonomy silently defaulted. | E11: bizos/pricing.py | F11: Fixed 2026-09-30 | G11: =COUNTIF(Results!$E$2:$E$381,A11)
A12: BUG-11 | B12: High | C12: Chat history not kept in UI | D12: Refresh or navigating away clears the conversation; no thread list or resume. | E12: ui/src/app/chat/page.tsx | F12: Fixed 2026-09-30 | G12: =COUNTIF(Results!$E$2:$E$381,A12)
A13: BUG-12 | B13: Medium | C13: No multiline chat input | D13: Single-line input; Shift+Enter submits and newlines are stripped. | E13: ui/src/app/chat/page.tsx | F13: Fixed 2026-09-30 | G13: =COUNTIF(Results!$E$2:$E$381,A13)
... A31: BUG-30 | B31: Low | C31: No execution-mode choice in chat UI | D31: Advise/Draft can only be set workspace-wide by admin. | E31: ui/src/app/chat/page.tsx | F31: Open | G31: =COUNTIF(Results!$E$2:$E$381,A31)
